Workbook

Sheet Summary
A1: Status | B1: reachedathub
A2: LP | B2: BLR LOCAL
A3: scm_master_category | B3: furniture
A5: Sum of item_quantity | B5: Column Labels
A6: Row Labels | B6: Breached | C6: P0 | D6: P1 | E6: Grand Total
A7: CFR | B7: 30 | C7: 8 | D7: 5 | E7: 43
A8: Outside Service Location | B8: 16 | C8: 9 | D8: 13 | E8: 38
A9: Planned | B9: 62 | C9: 31 | D9: 1 | E9: 94
A10: CNR | B10: 51 | C10: 38 | E10: 89
A11: Capcity Filled-Not Called | D11: 140 | E11: 140
A12: Grand Total | B12: 159 | C12: 86 | D12: 159 | E12: 404

Sheet Raw
A1: Platform | B1: order_random_id | C1: cx_name | D1: address | E1: pincode | F1: mobile_number | G1: alternate_mobile_number | H1: item_sku | I1: item_dimensions | J1: scm_master_category | K1: Material_code | L1: Product_Type | M1: storage_location | N1: item_quantity | O1: payment_type | P1: invoice_number | Q1: docket_number | R1: LP | S1: Order_Type | T1: Order_Status | U1: Order_Date | V1: Order_Confirmed_Date | W1: promised_dispatch | X1: Promised_EDD | Y1: docket_timestamp | Z1: shipped_timestamp | AA1: priority_local | AB1: escalated | AC1: escalation_type | AD1: Status | AE1: Previous Reason | AF1: Previous date | AG1: Response | AH1: Planning | AI1: Date | AJ1: Retail | AK1: CES | AL1: ESC | AM1: RTS | AN1: NDR | AO1: ODA | AP1: Manual | AQ1: Remarks
A2: Wakefit_Retail | B2: ORDER202603D4JJJj | C2: Neshan Shashi | D2: 415- Purna Kumb, 415, 7th A Main Rd, HRBR Layout 1st Block, HRBR Layout, Kalyan Nagar, Bengaluru, Karnataka | E2: 560043 | F2: 9380567157 | G2: 8296928367 | H2: WDINEKOVAC1ROBBK | J2: furniture | K2: 1001026053 | L2: Metal Dining Chair | M2: FG01 | N2: 1 | O2: ONLINE | P2: 26060590010670 | Q2: WFFWI223368 | R2: BLR LOCAL | S2: Replacement | T2: Docketed | U2: 2026-04-21 | V2: 2026-04-21 | W2: 2026-05-08 | X2: 2026-05-09 | Y2: 2026-06-22T09:36:22 | AA2: Breached | AB2: 0 | AD2: =VLOOKUP(Q2,'[1]an1asv_22-06-2026_06-23-43'!$B:$OA,3,0) -> reachedathub | AE2: =VLOOKUP(Q2,'[1]an1asv_22-06-2026_06-23-43'!$B:$OA,147,0) -> 0 | AF2: =VLOOKUP(Q2,'[1]an1asv_22-06-2026_06-23-43'!$B:$OA,48,0) -> 46195 | AG2: =VLOOKUP(F2,Response!$A:$B,2,0) -> #N/A | AH2: CNR | AJ2: =VLOOKUP(B2,'Ces, Esc, RTS and Retail'!$A:$B,2,0) -> #N/A | AK2: =VLOOKUP(F2,'Ces, Esc, RTS and Retail'!$D:$F,3,0) -> #N/A | AL2: =VLOOKUP(B2,'Ces, Esc, RTS and Retail'!$H:$H,1,0) -> #N/A | AM2: =VLOOKUP(Q2,'Ces, Esc, RTS and Retail'!$J:$J,1,0) -> #N/A | AN2: =VLOOKUP(Q2,'[2]Trip Manager Report(Updated)_V2'!$I:$Z,18,0) -> #N/A | AO2: =VLOOKUP(E2,'Ces, Esc, RTS and Retail'!$L:$L,1,0) -> #N/A | AP2: =VLOOKUP(Q2,Response!$H:$M,5,0) -> #N/A
A3: Wakefit_Retail | B3: ORDER202604EIG0pk | C3: Yash Sharma | D3: 1A , PMN Nest , Kaverappa Layout , Kadubeesanhalli | E3: 560103 | F3: 7976987821 | H3: WCFTSERAVACW | J3: furniture | K3: 1007120152 | L3: Coffee Table | M3: FG01 | N3: 1 | O3: ONLINE | P3: 26050590010369 | Q3: WFFI440688 | R3: BLR LOCAL | S3: Normal Order | T3: Shipped | U3: 2026-04-25 | V3: 2026-04-25 | W3: 2026-05-03 | X3: 2026-05-04 | Y3: 2026-05-19T23:35:57 | Z3: 2026-06-14T19:15:00 | AA3: Breached | AB3: 0 | AD3: =VLOOKUP(Q3,'[1]an1asv_22-06-2026_06-23-43'!$B:$OA,3,0) -> reachedathub | AE3: =VLOOKUP(Q3,'[1]an1asv_22-06-2026_06-23-43'!$B:$OA,147,0) -> Customer Request for Future Date Delivery | AF3: =VLOOKUP(Q3,'[1]an1asv_22-06-2026_06-23-43'!$B:$OA,48,0) -> 46205 | AG3: =VLOOKUP(F3,Response!$A:$B,2,0) -> #N/A | AH3: CFR | AI3: =AF3 -> 46205 | AJ3: =VLOOKUP(B3,'Ces, Esc, RTS and Retail'!$A:$B,2,0) -> #N/A | AK3: =VLOOKUP(F3,'Ces, Esc, RTS and Retail'!$D:$F,3,0) -> #N/A | AL3: =VLOOKUP(B3,'Ces, Esc, RTS and Retail'!$H:$H,1,0) -> #N/A | AM3: =VLOOKUP(Q3,'Ces, Esc, RTS and Retail'!$J:$J,1,0) -> #N/A | AN3: =VLOOKUP(Q3,'[2]Trip Manager Report(Updated)_V2'!$I:$Z,18,0) -> #N/A | AO3: =VLOOKUP(E3,'Ces, Esc, RTS and Retail'!$L:$L,1,0) -> #N/A | AP3: =VLOOKUP(Q3,Response!$H:$M,5,0) -> #N/A
A4: Wakefit_Retail | B4: ORDER202604xD3wcq | C4: Nisarga DS | D4: 108 T John Serenity, Chunchunkuppe village Tavarekere Hobli Bangalore south taluk | E4: 562130 | F4: 7483688930 | G4: 8892415163 | H4: WEWB7872HYSTESSERCW | I4: 78x72 inch | J4: furniture | K4: 1001033589 | L4: Engineered Wood Bed | M4: FG01 | N4: 1 | O4: ONLINE | P4: 26050590010417 | Q4: WFFI440732 | R4: BLR LOCAL | S4: Normal Order | T4: Shipped | U4: 2026-04-26 | V4: 2026-04-27 | W4: 2026-05-21 | X4: 2026-05-25 | Y4: 2026-05-19T23:41:42 | Z4: 2026-06-19T21:39:56 | AA4: Breached | AB4: 0 | AD4: =VLOOKUP(Q4,'[1]an1asv_22-06-2026_06-23-43'!$B:$OA,3,0) -> reachedathub | AE4: =VLOOKUP(Q4,'[1]an1asv_22-06-2026_06-23-43'!$B:$OA,147,0) -> Outside Service Location | AF4: =VLOOKUP(Q4,'[1]an1asv_22-06-2026_06-23-43'!$B:$OA,48,0) -> 46196 | AG4: =VLOOKUP(F4,Response!$A:$B,2,0) -> #N/A | AH4: Outside Service Location | AJ4: =VLOOKUP(B4,'Ces, Esc, RTS and Retail'!$A:$B,2,0) -> #N/A | AK4: =VLOOKUP(F4,'Ces, Esc, RTS and Retail'!$D:$F,3,0) -> #N/A | AL4: =VLOOKUP(B4,'Ces, Esc, RTS and Retail'!$H:$H,1,0) -> #N/A | AM4: =VLOOKUP(Q4,'Ces, Esc, RTS and Retail'!$J:$J,1,0) -> #N/A | AN4: =VLOOKUP(Q4,'[2]Trip Manager Report(Updated)_V2'!$I:$Z,18,0) -> #N/A | AO4: =VLOOKUP(E4,'Ces, Esc, RTS and Retail'!$L:$L,1,0) -> 562130 | AP4: =VLOOKUP(Q4,Response!$H:$M,5,0) -> #N/A
A5: Flipkart | B5: OD437458319078931100 | C5: Sudhanshu Jena | D5: Flat 103 , Unnati Bhavan Maithri Layout, 3rd Cross Road, V S Reddy Colony, Kadugodi | E5: 560067 | F5: 8342061533 | H5: WEWB7860STAURUSWE | I5: 78x60 inch | J5: furniture | K5: 1001024790 | L5: Engineered Wood Bed | M5: FG01 | N5: 1 | O5: ONLINE | P5: 26050590002325 | Q5: WFFI430862 | R5: BLR LOCAL | S5: Normal Order | T5: Shipped | U5: 2026-05-02 | V5: 2026-05-02 | W5: 2026-05-06 | X5: 2026-05-07 | Y5: 2026-05-06T09:41:09 | Z5: 2026-06-01T20:16:46 | AA5: Breached | AB5: 0 | AD5: =VLOOKUP(Q5,'[1]an1asv_22-06-2026_06-23-43'!$B:$OA,3,0) -> reachedathub | AE5: =VLOOKUP(Q5,'[1]an1asv_22-06-2026_06-23-43'!$B:$OA,147,0) -> Customer Request for Future Date Delivery | AF5: =VLOOKUP(Q5,'[1]an1asv_22-06-2026_06-23-43'!$B:$OA,48,0) -> 46208 | AG5: =VLOOKUP(F5,Response!$A:$B,2,0) -> #N/A | AH5: CFR | AI5: =AF5 -> 46208 | AJ5: =VLOOKUP(B5,'Ces, Esc, RTS and Retail'!$A:$B,2,0) -> #N/A | AK5: =VLOOKUP(F5,'Ces, Esc, RTS and Retail'!$D:$F,3,0) -> #N/A | AL5: =VLOOKUP(B5,'Ces, Esc, RTS and Retail'!$H:$H,1,0) -> #N/A | AM5: =VLOOKUP(Q5,'Ces, Esc, RTS and Retail'!$J:$J,1,0) -> #N/A | AN5: =VLOOKUP(Q5,'[2]Trip Manager Report(Updated)_V2'!$I:$Z,18,0) -> #N/A | AO5: =VLOOKUP(E5,'Ces, Esc, RTS and Retail'!$L:$L,1,0) -> #N/A | AP5: =VLOOKUP(Q5,Response!$H:$M,5,0) -> #N/A
A6: Amazon | B6: 403-5995909-0108356 | C6: Sahana | D6: Sattva Anugraha Tower 16 302, Sattva Anugraha, Kamakshipalya | E6: 560079 | F6: 9980085231 | G6: 9980085231 | H6: WEWB7872HYSUPOGRMARS | I6: 78x72 inch | J6: furniture | K6: 1007002830 | L6: Engineered Wood Bed | M6: FG01 | N6: 1 | O6: ONLINE | P6: 26050590011277 | Q6: WFFI441318 | R6: BLR LOCAL | S6: Normal Order | T6: Shipped | U6: 2026-05-10 | V6: 2026-05-10 | W6: 2026-05-18 | X6: 2026-05-21 | Y6: 2026-05-21T08:06:10 | Z6: 2026-06-09T22:17:40 | AA6: Breached | AB6: 0 | AD6: =VLOOKUP(Q6,'[1]an1asv_22-06-2026_06-23-43'!$B:$OA,3,0) -> reachedathub | AE6: =VLOOKUP(Q6,'[1]an1asv_22-06-2026_06-23-43'!$B:$OA,147,0) -> Customer Request for Future Date Delivery | AF6: =VLOOKUP(Q6,'[1]an1asv_22-06-2026_06-23-43'!$B:$OA,48,0) -> 46200 | AG6: =VLOOKUP(F6,Response!$A:$B,2,0) -> #N/A | AH6: CFR | AI6: =AF6 -> 46200 | AJ6: =VLOOKUP(B6,'Ces, Esc, RTS and Retail'!$A:$B,2,0) -> #N/A | AK6: =VLOOKUP(F6,'Ces, Esc, RTS and Retail'!$D:$F,3,0) -> #N/A | AL6: =VLOOKUP(B6,'Ces, Esc, RTS and Retail'!$H:$H,1,0) -> #N/A | AM6: =VLOOKUP(Q6,'Ces, Esc, RTS and Retail'!$J:$J,1,0) -> #N/A | AN6: =VLOOKUP(Q6,'[2]Trip Manager Report(Updated)_V2'!$I:$Z,18,0) -> #N/A | AO6: =VLOOKUP(E6,'Ces, Esc, RTS and Retail'!$L:$L,1,0) -> #N/A | AP6: =VLOOKUP(Q6,Response!$H:$M,5,0) -> #N/A
A7: Wakefit_Retail | B7: ORDER202605DYn9qM | C7: Remjith TK | D7: Tower 3, Flat No 903, 9th Floor, Purva Atmosphere,Thanisandra. | E7: 560077 | F7: 9535740011 | H7: WEWB7860HYSNIXCW | I7: 78x60 inch | J7: furniture | K7: 1001039591 | L7: Engineered Wood Bed | M7: FG01 | N7: 1 | O7: ONLINE | P7: 26060590005593 | Q7: WFFI455027 | R7: BLR LOCAL | S7: Normal Order | T7: Docketed | U7: 2026-05-12 | V7: 2026-05-12 | W7: 2026-06-02 | X7: 2026-06-03 | Y7: 2026-06-11T21:36:27 | AA7: Breached | AB7: 0 | AD7: =VLOOKUP(Q7,'[1]an1asv_22-06-2026_06-23-43'!$B:$OA,3,0) -> reachedathub | AE7: =VLOOKUP(Q7,'[1]an1asv_22-06-2026_06-23-43'!$B:$OA,147,0) -> Customer Request for Future Date Delivery | AF7: =VLOOKUP(Q7,'[1]an1asv_22-06-2026_06-23-43'!$B:$OA,48,0) -> 46199 | AG7: =VLOOKUP(F7,Response!$A:$B,2,0) -> #N/A | AH7: CFR | AI7: =AF7 -> 46199 | AJ7: =VLOOKUP(B7,'Ces, Esc, RTS and Retail'!$A:$B,2,0) -> #N/A | AK7: =VLOOKUP(F7,'Ces, Esc, RTS and Retail'!$D:$F,3,0) -> #N/A | AL7: =VLOOKUP(B7,'Ces, Esc, RTS and Retail'!$H:$H,1,0) -> #N/A | AM7: =VLOOKUP(Q7,'Ces, Esc, RTS and Retail'!$J:$J,1,0) -> #N/A | AN7: =VLOOKUP(Q7,'[2]Trip Manager Report(Updated)_V2'!$I:$Z,18,0) -> #N/A | AO7: =VLOOKUP(E7,'Ces, Esc, RTS and Retail'!$L:$L,1,0) -> #N/A | AP7: =VLOOKUP(Q7,Response!$H:$M,5,0) -> #N/A
A8: Wakefit | B8: ORDER202605t2y4PB | C8: Avinash Chawla | D8: B-014, 1, Sansidh Galaxy, B Block, Rachenahalli | E8: 560077 | F8: 9823670557 | G8: 7276070557 | H8: WEWB7872HYSTESSERCW | I8: 78x72 inch | J8: furniture | K8: 1001033589 | L8: Engineered Wood Bed | M8: FG01 | N8: 1 | O8: ONLINE | P8: 26060590008303 | Q8: WFFI458051 | R8: BLR LOCAL | S8: Normal Order | T8: Docketed | U8: 2026-05-18 | V8: 2026-05-18 | W8: 2026-06-17 | X8: 2026-06-18 | Y8: 2026-06-17T12:06:09 | AA8: Breached | AB8: 0 | AD8: =VLOOKUP(Q8,'[1]an1asv_22-06-2026_06-23-43'!$B:$OA,3,0) -> reachedathub | AE8: =VLOOKUP(Q8,'[1]an1asv_22-06-2026_06-23-43'!$B:$OA,147,0) -> CNR/ No Date from Customer | AF8: =VLOOKUP(Q8,'[1]an1asv_22-06-2026_06-23-43'!$B:$OA,48,0) -> 46196 | AG8: =VLOOKUP(F8,Response!$A:$B,2,0) -> #N/A | AH8: CNR | AJ8: =VLOOKUP(B8,'Ces, Esc, RTS and Retail'!$A:$B,2,0) -> #N/A | AK8: =VLOOKUP(F8,'Ces, Esc, RTS and Retail'!$D:$F,3,0) -> #N/A | AL8: =VLOOKUP(B8,'Ces, Esc, RTS and Retail'!$H:$H,1,0) -> #N/A | AM8: =VLOOKUP(Q8,'Ces, Esc, RTS and Retail'!$J:$J,1,0) -> #N/A | AN8: =VLOOKUP(Q8,'[2]Trip Manager Report(Updated)_V2'!$I:$Z,18,0) -> #N/A | AO8: =VLOOKUP(E8,'Ces, Esc, RTS and Retail'!$L:$L,1,0) -> #N/A | AP8: =VLOOKUP(Q8,Response!$H:$M,5,0) -> #N/A
A9: Wakefit_Retail | B9: ORDER202605f7wbcG | C9: Paniraj thanthry | D9: #405, 4th floor, Sairam Gardenia, near RGA Tech Park & Decathlon mart, Hadosiddapura, Chikkakannalli, Kodathi JHC, Karnatak | E9: 560035 | F9: 8431567630 | G9: 8431567630 | H9: WEWB7860STESSERCW | I9: 78x60 inch | J9: furniture | K9: 1001033592 | L9: Engineered Wood Bed | M9: FG01 | N9: 1 | O9: ONLINE | P9: 26060590008782 | Q9: WFFI458444 | R9: BLR LOCAL | S9: Normal Order | T9: Shipped | U9: 2026-05-19 | V9: 2026-05-19 | W9: 2026-06-18 | X9: 2026-06-19 | Y9: 2026-06-17T23:21:10 | Z9: 2026-06-18T21:32:44 | AA9: Breached | AB9: 0 | AD9: =VLOOKUP(Q9,'[1]an1asv_22-06-2026_06-23-43'!$B:$OA,3,0) -> reachedathub | AE9: =VLOOKUP(Q9,'[1]an1asv_22-06-2026_06-23-43'!$B:$OA,147,0) -> Customer Request for Future Date Delivery | AF9: =VLOOKUP(Q9,'[1]an1asv_22-06-2026_06-23-43'!$B:$OA,48,0) -> 46196 | AG9: =VLOOKUP(F9,Response!$A:$B,2,0) -> #N/A | AH9: Planned | AJ9: =VLOOKUP(B9,'Ces, Esc, RTS and Retail'!$A:$B,2,0) -> #N/A | AK9: =VLOOKUP(F9,'Ces, Esc, RTS and Retail'!$D:$F,3,0) -> #N/A | AL9: =VLOOKUP(B9,'Ces, Esc, RTS and Retail'!$H:$H,1,0) -> #N/A | AM9: =VLOOKUP(Q9,'Ces, Esc, RTS and Retail'!$J:$J,1,0) -> #N/A | AN9: =VLOOKUP(Q9,'[2]Trip Manager Report(Updated)_V2'!$I:$Z,18,0) -> #N/A | AO9: =VLOOKUP(E9,'Ces, Esc, RTS and Retail'!$L:$L,1,0) -> #N/A | AP9: =VLOOKUP(Q9,Response!$H:$M,5,0) -> #N/A
A10: Wakefit | B10: ORDER202605M3lGeY | C10: Bhaskar Anand | D10: A1203, 12, Sanjeevini Aarna, A1203 sanjeevini Aarna dandupalya village hoskote highway | E10: 562114 | F10: 9535690956 | G10: 9535690956 | H10: WUWB7872SVAMANTHO | I10: 78x72 inch | J10: furniture | K10: 1007002695 | L10: Upholstered Beds | M10: FG01 | N10: 1 | O10: ONLINE | P10: 26050590013705 | Q10: WFFI444022 | R10: BLR LOCAL | S10: Normal Order | T10: Docketed | U10: 2026-05-06 | V10: 2026-05-20 | W10: 2026-06-19 | X10: 2026-06-19 | Y10: 2026-05-25T09:11:08 | AA10: Breached | AB10: 0 | AD10: =VLOOKUP(Q10,'[1]an1asv_22-06-2026_06-23-43'!$B:$OA,3,0) -> reachedathub | AE10: =VLOOKUP(Q10,'[1]an1asv_22-06-2026_06-23-43'!$B:$OA,147,0) -> Outside Service Location | AF10: =VLOOKUP(Q10,'[1]an1asv_22-06-2026_06-23-43'!$B:$OA,48,0) -> 46196 | AG10: =VLOOKUP(F10,Response!$A:$B,2,0) -> #N/A | AH10: Outside Service Location | AJ10: =VLOOKUP(B10,'Ces, Esc, RTS and Retail'!$A:$B,2,0) -> #N/A | AK10: =VLOOKUP(F10,'Ces, Esc, RTS and Retail'!$D:$F,3,0) -> #N/A | AL10: =VLOOKUP(B10,'Ces, Esc, RTS and Retail'!$H:$H,1,0) -> #N/A | AM10: =VLOOKUP(Q10,'Ces, Esc, RTS and Retail'!$J:$J,1,0) -> #N/A | AN10: =VLOOKUP(Q10,'[2]Trip Manager Report(Updated)_V2'!$I:$Z,18,0) -> #N/A | AO10: =VLOOKUP(E10,'Ces, Esc, RTS and Retail'!$L:$L,1,0) -> 562114 | AP10: =VLOOKUP(Q10,Response!$H:$M,5,0) -> #N/A
A11: Wakefit_Retail | B11: ORDER202605DGbKfC | C11: Hariharan | D11: #51 3rd floor 1st main 4th cross Swami vivekanda nagar | E11: 562114 | F11: 8526999803 | G11: 8526999803 | H11: WEWB7872NONUPOGRORIONR2 | I11: 78x72 inch | J11: furniture | K11: 1001019166 | L11: Engineered Wood Bed | M11: FG01 | N11: 1 | O11: ONLINE | P11: 26050590016916 | Q11: WFFI448123 | R11: BLR LOCAL | S11: Normal Order | T11: Shipped | U11: 2026-05-21 | V11: 2026-05-21 | W11: 2026-06-07 | X11: 2026-06-10 | Y11: 2026-05-30T20:11:32 | Z11: 2026-06-02T22:37:57 | AA11: Breached | AB11: 0 | AD11: =VLOOKUP(Q11,'[1]an1asv_22-06-2026_06-23-43'!$B:$OA,3,0) -> reachedathub | AE11: =VLOOKUP(Q11,'[1]an1asv_22-06-2026_06-23-43'!$B:$OA,147,0) -> Outside Service Location | AF11: =VLOOKUP(Q11,'[1]an1asv_22-06-2026_06-23-43'!$B:$OA,48,0) -> 46196 | AG11: =VLOOKUP(F11,Response!$A:$B,2,0) -> #N/A | AH11: Outside Service Location | AJ11: =VLOOKUP(B11,'Ces, Esc, RTS and Retail'!$A:$B,2,0) -> #N/A | AK11: =VLOOKUP(F11,'Ces, Esc, RTS and Retail'!$D:$F,3,0) -> #N/A | AL11: =VLOOKUP(B11,'Ces, Esc, RTS and Retail'!$H:$H,1,0) -> #N/A | AM11: =VLOOKUP(Q11,'Ces, Esc, RTS and Retail'!$J:$J,1,0) -> #N/A | AN11: =VLOOKUP(Q11,'[2]Trip Manager Report(Updated)_V2'!$I:$Z,18,0) -> #N/A | AO11: =VLOOKUP(E11,'Ces, Esc, RTS and Retail'!$L:$L,1,0) -> 562114 | AP11: =VLOOKUP(Q11,Response!$H:$M,5,0) -> #N/A
A12: Wakefit_Retail | B12: ORDER202605TXMROy | C12: Anshuman Mohanto | D12: D-102, ITC Garden Enclave, Jakkur Plantation, Jakkur, 560064, Bengaluru (L) : Jakkur Plantation BENGALURU, KARNATAKA - 560064 | E12: 560064 | F12: 9659979555 | H12: WDINESOMARIS6 | J12: furniture | K12: 1001039969 | L12: Dining Set | M12: FG01 | N12: 1 | O12: ONLINE | P12: 26060590009480 | Q12: WFFI459246 | R12: BLR LOCAL | S12: Replacement | T12: Shipped | U12: 2026-05-22 | V12: 2026-05-22 | W12: 2026-06-19 | X12: 2026-06-22 | Y12: 2026-06-19T11:07:45 | Z12: 2026-06-20T20:45:33 | AA12: Breached | AB12: 0 | AD12: =VLOOKUP(Q12,'[1]an1asv_22-06-2026_06-23-43'!$B:$OA,3,0) -> reachedathub | AE12: =VLOOKUP(Q12,'[1]an1asv_22-06-2026_06-23-43'!$B:$OA,147,0) -> INSUFFICIENT TIME | AF12: =VLOOKUP(Q12,'[1]an1asv_22-06-2026_06-23-43'!$B:$OA,48,0) -> 46195 | AG12: =VLOOKUP(F12,Response!$A:$B,2,0) -> #N/A | AH12: Planned | AJ12: =VLOOKUP(B12,'Ces, Esc, RTS and Retail'!$A:$B,2,0) -> #N/A | AK12: =VLOOKUP(F12,'Ces, Esc, RTS and Retail'!$D:$F,3,0) -> #N/A | AL12: =VLOOKUP(B12,'Ces, Esc, RTS and Retail'!$H:$H,1,0) -> #N/A | AM12: =VLOOKUP(Q12,'Ces, Esc, RTS and Retail'!$J:$J,1,0) -> #N/A | AN12: =VLOOKUP(Q12,'[2]Trip Manager Report(Updated)_V2'!$I:$Z,18,0) -> INSUFFICIENT TIME | AO12: =VLOOKUP(E12,'Ces, Esc, RTS and Retail'!$L:$L,1,0) -> #N/A | AP12: =VLOOKUP(Q12,Response!$H:$M,5,0) -> #N/A
A13: Wakefit_Retail | B13: ORDER202605JFeLOb | C13: Suresh Basimi | D13: S-1001, Ground Floor, BEL Layout, Bharath Nagar | E13: 560091 | F13: 7975673365 | G13: 7676268891 | H13: WEWB7860STESSERCW | I13: 78x60 inch | J13: furniture | K13: 1001033592 | L13: Engineered Wood Bed | M13: FG01 | N13: 1 | O13: ONLINE | P13: 26060590010666 | Q13: WFFI460892 | R13: BLR LOCAL | S13: Normal Order | T13: Docketed | U13: 2026-05-23 | V13: 2026-05-23 | W13: 2026-06-21 | X13: 2026-06-22 | Y13: 2026-06-22T09:36:14 | AA13: Breached | AB13: 0 | AD13: =VLOOKUP(Q13,'[1]an1asv_22-06-2026_06-23-43'!$B:$OA,3,0) -> reachedathub | AE13: =VLOOKUP(Q13,'[1]an1asv_22-06-2026_06-23-43'!$B:$OA,147,0) -> 0 | AF13: =VLOOKUP(Q13,'[1]an1asv_22-06-2026_06-23-43'!$B:$OA,48,0) -> 46195 | AG13: =VLOOKUP(F13,Response!$A:$B,2,0) -> #N/A | AH13: CNR | AJ13: =VLOOKUP(B13,'Ces, Esc, RTS and Retail'!$A:$B,2,0) -> #N/A | AK13: =VLOOKUP(F13,'Ces, Esc, RTS and Retail'!$D:$F,3,0) -> #N/A | AL13: =VLOOKUP(B13,'Ces, Esc, RTS and Retail'!$H:$H,1,0) -> #N/A | AM13: =VLOOKUP(Q13,'Ces, Esc, RTS and Retail'!$J:$J,1,0) -> #N/A | AN13: =VLOOKUP(Q13,'[2]Trip Manager Report(Updated)_V2'!$I:$Z,18,0) -> #N/A | AO13: =VLOOKUP(E13,'Ces, Esc, RTS and Retail'!$L:$L,1,0) -> #N/A | AP13: =VLOOKUP(Q13,Response!$H:$M,5,0) -> #N/A
A14: Wakefit | B14: ORDER202605gVn2hF | C14: Rishabh Gupta | D14: 1B 1102, 11, Suncity Gloria Apartments, Series 01-04, Sarjapur Dommasandra Rd, | E14: 560035 | F14: 9551997926 | G14: 9551997926 | H14: WDINEKOVAC1CGBK | J14: furniture | K14: 1001026055 | L14: Metal Dining Chair | M14: FG01 | N14: 1 | O14: ONLINE | P14: 26060590010253 | Q14: WFFWI223222 | R14: BLR LOCAL | S14: Normal Order | T14: Docketed | U14: 2026-05-23 | V14: 2026-05-23 | W14: 2026-06-21 | X14: 2026-06-22 | Y14: 2026-06-21T11:42:27 | AA14: Breached | AB14: 0 | AD14: =VLOOKUP(Q14,'[1]an1asv_22-06-2026_06-23-43'!$B:$OA,3,0) -> reachedathub | AE14: =VLOOKUP(Q14,'[1]an1asv_22-06-2026_06-23-43'!$B:$OA,147,0) -> 0 | AF14: =VLOOKUP(Q14,'[1]an1asv_22-06-2026_06-23-43'!$B:$OA,48,0) -> 46195 | AG14: =VLOOKUP(F14,Response!$A:$B,2,0) -> 0607 | AH14: CFR | AI14: 46209 | AJ14: =VLOOKUP(B14,'Ces, Esc, RTS and Retail'!$A:$B,2,0) -> #N/A | AK14: =VLOOKUP(F14,'Ces, Esc, RTS and Retail'!$D:$F,3,0) -> #N/A | AL14: =VLOOKUP(B14,'Ces, Esc, RTS and Retail'!$H:$H,1,0) -> #N/A | AM14: =VLOOKUP(Q14,'Ces, Esc, RTS and Retail'!$J:$J,1,0) -> #N/A | AN14: =VLOOKUP(Q14,'[2]Trip Manager Report(Updated)_V2'!$I:$Z,18,0) -> #N/A | AO14: =VLOOKUP(E14,'Ces, Esc, RTS and Retail'!$L:$L,1,0) -> #N/A | AP14: =VLOOKUP(Q14,Response!$H:$M,5,0) -> #N/A
A15: Wakefit | B15: ORDER202605gVn2hF | C15: Rishabh Gupta | D15: 1B 1102, 11, Suncity Gloria Apartments, Series 01-04, Sarjapur Dommasandra Rd, | E15: 560035 | F15: 9551997926 | G15: 9551997926 | H15: WDINEKOVAC1CGBK | J15: furniture | K15: 1001026055 | L15: Metal Dining Chair | M15: FG01 | N15: 1 | O15: ONLINE | P15: 26060590010256 | Q15: WFFWI223224 | R15: BLR LOCAL | S15: Normal Order | T15: Docketed | U15: 2026-05-23 | V15: 2026-05-23 | W15: 2026-06-21 | X15: 2026-06-22 | Y15: 2026-06-21T11:42:27 | AA15: Breached | AB15: 0 | AD15: =VLOOKUP(Q15,'[1]an1asv_22-06-2026_06-23-43'!$B:$OA,3,0) -> reachedathub | AE15: =VLOOKUP(Q15,'[1]an1asv_22-06-2026_06-23-43'!$B:$OA,147,0) -> 0 | AF15: =VLOOKUP(Q15,'[1]an1asv_22-06-2026_06-23-43'!$B:$OA,48,0) -> 46195 | AG15: =VLOOKUP(F15,Response!$A:$B,2,0) -> 0607 | AH15: CFR | AI15: 46209 | AJ15: =VLOOKUP(B15,'Ces, Esc, RTS and Retail'!$A:$B,2,0) -> #N/A | AK15: =VLOOKUP(F15,'Ces, Esc, RTS and Retail'!$D:$F,3,0) -> #N/A | AL15: =VLOOKUP(B15,'Ces, Esc, RTS and Retail'!$H:$H,1,0) -> #N/A | AM15: =VLOOKUP(Q15,'Ces, Esc, RTS and Retail'!$J:$J,1,0) -> #N/A | AN15: =VLOOKUP(Q15,'[2]Trip Manager Report(Updated)_V2'!$I:$Z,18,0) -> #N/A | AO15: =VLOOKUP(E15,'Ces, Esc, RTS and Retail'!$L:$L,1,0) -> #N/A | AP15: =VLOOKUP(Q15,Response!$H:$M,5,0) -> #N/A
A16: Wakefit | B16: ORDER202605gVn2hF | C16: Rishabh Gupta | D16: 1B 1102, 11, Suncity Gloria Apartments, Series 01-04, Sarjapur Dommasandra Rd, | E16: 560035 | F16: 9551997926 | G16: 9551997926 | H16: WDINEKOVAC1CGBK | J16: furniture | K16: 1001026055 | L16: Metal Dining Chair | M16: FG01 | N16: 1 | O16: ONLINE | P16: 26060590010260 | Q16: WFFWI223225 | R16: BLR LOCAL | S16: Normal Order | T16: Docketed | U16: 2026-05-23 | V16: 2026-05-23 | W16: 2026-06-21 | X16: 2026-06-22 | Y16: 2026-06-21T11:42:27 | AA16: Breached | AB16: 0 | AD16: =VLOOKUP(Q16,'[1]an1asv_22-06-2026_06-23-43'!$B:$OA,3,0) -> reachedathub | AE16: =VLOOKUP(Q16,'[1]an1asv_22-06-2026_06-23-43'!$B:$OA,147,0) -> 0 | AF16: =VLOOKUP(Q16,'[1]an1asv_22-06-2026_06-23-43'!$B:$OA,48,0) -> 46195 | AG16: =VLOOKUP(F16,Response!$A:$B,2,0) -> 0607 | AH16: CFR | AI16: 46209 | AJ16: =VLOOKUP(B16,'Ces, Esc, RTS and Retail'!$A:$B,2,0) -> #N/A | AK16: =VLOOKUP(F16,'Ces, Esc, RTS and Retail'!$D:$F,3,0) -> #N/A | AL16: =VLOOKUP(B16,'Ces, Esc, RTS and Retail'!$H:$H,1,0) -> #N/A | AM16: =VLOOKUP(Q16,'Ces, Esc, RTS and Retail'!$J:$J,1,0) -> #N/A | AN16: =VLOOKUP(Q16,'[2]Trip Manager Report(Updated)_V2'!$I:$Z,18,0) -> #N/A | AO16: =VLOOKUP(E16,'Ces, Esc, RTS and Retail'!$L:$L,1,0) -> #N/A | AP16: =VLOOKUP(Q16,Response!$H:$M,5,0) -> #N/A
A17: Wakefit | B17: ORDER202605gVn2hF | C17: Rishabh Gupta | D17: 1B 1102, 11, Suncity Gloria Apartments, Series 01-04, Sarjapur Dommasandra Rd, | E17: 560035 | F17: 9551997926 | G17: 9551997926 | H17: WDINEKOVAC1CGBK | J17: furniture | K17: 1001026055 | L17: Metal Dining Chair | M17: FG01 | N17: 1 | O17: ONLINE | P17: 26060590010264 | Q17: WFFWI223226 | R17: BLR LOCAL | S17: Normal Order | T17: Docketed | U17: 2026-05-23 | V17: 2026-05-23 | W17: 2026-06-21 | X17: 2026-06-22 | Y17: 2026-06-21T11:42:27 | AA17: Breached | AB17: 0 | AD17: =VLOOKUP(Q17,'[1]an1asv_22-06-2026_06-23-43'!$B:$OA,3,0) -> reachedathub | AE17: =VLOOKUP(Q17,'[1]an1asv_22-06-2026_06-23-43'!$B:$OA,147,0) -> 0 | AF17: =VLOOKUP(Q17,'[1]an1asv_22-06-2026_06-23-43'!$B:$OA,48,0) -> 46195 | AG17: =VLOOKUP(F17,Response!$A:$B,2,0) -> 0607 | AH17: CFR | AI17: 46209 | AJ17: =VLOOKUP(B17,'Ces, Esc, RTS and Retail'!$A:$B,2,0) -> #N/A | AK17: =VLOOKUP(F17,'Ces, Esc, RTS and Retail'!$D:$F,3,0) -> #N/A | AL17: =VLOOKUP(B17,'Ces, Esc, RTS and Retail'!$H:$H,1,0) -> #N/A | AM17: =VLOOKUP(Q17,'Ces, Esc, RTS and Retail'!$J:$J,1,0) -> #N/A | AN17: =VLOOKUP(Q17,'[2]Trip Manager Report(Updated)_V2'!$I:$Z,18,0) -> #N/A | AO17: =VLOOKUP(E17,'Ces, Esc, RTS and Retail'!$L:$L,1,0) -> #N/A | AP17: =VLOOKUP(Q17,Response!$H:$M,5,0) -> #N/A
A18: Wakefit | B18: ORDER202605gVn2hF | C18: Rishabh Gupta | D18: 1B 1102, 11, Suncity Gloria Apartments, Series 01-04, Sarjapur Dommasandra Rd, | E18: 560035 | F18: 9551997926 | G18: 9551997926 | H18: WDINEKOVAC1CGBK | J18: furniture | K18: 1001026055 | L18: Metal Dining Chair | M18: FG01 | N18: 1 | O18: ONLINE | P18: 26060590010266 | Q18: WFFWI223227 | R18: BLR LOCAL | S18: Normal Order | T18: Docketed | U18: 2026-05-23 | V18: 2026-05-23 | W18: 2026-06-21 | X18: 2026-06-22 | Y18: 2026-06-21T11:42:27 | AA18: Breached | AB18: 0 | AD18: =VLOOKUP(Q18,'[1]an1asv_22-06-2026_06-23-43'!$B:$OA,3,0) -> reachedathub | AE18: =VLOOKUP(Q18,'[1]an1asv_22-06-2026_06-23-43'!$B:$OA,147,0) -> 0 | AF18: =VLOOKUP(Q18,'[1]an1asv_22-06-2026_06-23-43'!$B:$OA,48,0) -> 46195 | AG18: =VLOOKUP(F18,Response!$A:$B,2,0) -> 0607 | AH18: CFR | AI18: 46209 | AJ18: =VLOOKUP(B18,'Ces, Esc, RTS and Retail'!$A:$B,2,0) -> #N/A | AK18: =VLOOKUP(F18,'Ces, Esc, RTS and Retail'!$D:$F,3,0) -> #N/A | AL18: =VLOOKUP(B18,'Ces, Esc, RTS and Retail'!$H:$H,1,0) -> #N/A | AM18: =VLOOKUP(Q18,'Ces, Esc, RTS and Retail'!$J:$J,1,0) -> #N/A | AN18: =VLOOKUP(Q18,'[2]Trip Manager Report(Updated)_V2'!$I:$Z,18,0) -> #N/A | AO18: =VLOOKUP(E18,'Ces, Esc, RTS and Retail'!$L:$L,1,0) -> #N/A | AP18: =VLOOKUP(Q18,Response!$H:$M,5,0) -> #N/A
A19: Wakefit | B19: ORDER202605gVn2hF | C19: Rishabh Gupta | D19: 1B 1102, 11, Suncity Gloria Apartments, Series 01-04, Sarjapur Dommasandra Rd, | E19: 560035 | F19: 9551997926 | G19: 9551997926 | H19: WDINEKOVAC1CGBK | J19: furniture | K19: 1001026055 | L19: Metal Dining Chair | M19: FG01 | N19: 1 | O19: ONLINE | P19: 26060590010272 | Q19: WFFWI223228 | R19: BLR LOCAL | S19: Normal Order | T19: Docketed | U19: 2026-05-23 | V19: 2026-05-23 | W19: 2026-06-21 | X19: 2026-06-22 | Y19: 2026-06-21T11:42:27 | AA19: Breached | AB19: 0 | AD19: =VLOOKUP(Q19,'[1]an1asv_22-06-2026_06-23-43'!$B:$OA,3,0) -> reachedathub | AE19: =VLOOKUP(Q19,'[1]an1asv_22-06-2026_06-23-43'!$B:$OA,147,0) -> 0 | AF19: =VLOOKUP(Q19,'[1]an1asv_22-06-2026_06-23-43'!$B:$OA,48,0) -> 46195 | AG19: =VLOOKUP(F19,Response!$A:$B,2,0) -> 0607 | AH19: CFR | AI19: 46209 | AJ19: =VLOOKUP(B19,'Ces, Esc, RTS and Retail'!$A:$B,2,0) -> #N/A | AK19: =VLOOKUP(F19,'Ces, Esc, RTS and Retail'!$D:$F,3,0) -> #N/A | AL19: =VLOOKUP(B19,'Ces, Esc, RTS and Retail'!$H:$H,1,0) -> #N/A | AM19: =VLOOKUP(Q19,'Ces, Esc, RTS and Retail'!$J:$J,1,0) -> #N/A | AN19: =VLOOKUP(Q19,'[2]Trip Manager Report(Updated)_V2'!$I:$Z,18,0) -> #N/A | AO19: =VLOOKUP(E19,'Ces, Esc, RTS and Retail'!$L:$L,1,0) -> #N/A | AP19: =VLOOKUP(Q19,Response!$H:$M,5,0) -> #N/A
A20: Amazon | B20: 406-1344094-7380325 | C20: Rituparna singh | D20: A 1304 ELV Kingsland Borewell road Whitefield,Opposite to Top in town superstore | E20: 560066 | F20: 7899760082 | H20: WBSBURNS4 | J20: furniture | K20: 1003010018 | L20: Bookshelf | M20: FG01 | N20: 1 | O20: ONLINE | P20: 26060590003737 | Q20: WFFI452866 | R20: BLR LOCAL | S20: Normal Order | T20: Shipped | U20: 2026-05-23 | V20: 2026-05-23 | W20: 2026-06-10 | X20: 2026-06-16 | Y20: 2026-06-07T15:36:00 | Z20: 2026-06-09T21:09:45 | AA20: Breached | AB20: 0 | AD20: =VLOOKUP(Q20,'[1]an1asv_22-06-2026_06-23-43'!$B:$OA,3,0) -> reachedathub | AE20: =VLOOKUP(Q20,'[1]an1asv_22-06-2026_06-23-43'!$B:$OA,147,0) -> Customer Request for Future Date Delivery | AF20: =VLOOKUP(Q20,'[1]an1asv_22-06-2026_06-23-43'!$B:$OA,48,0) -> 46200 | AG20: =VLOOKUP(F20,Response!$A:$B,2,0) -> #N/A | AH20: CFR | AI20: =AF20 -> 46200 | AJ20: =VLOOKUP(B20,'Ces, Esc, RTS and Retail'!$A:$B,2,0) -> #N/A | AK20: =VLOOKUP(F20,'Ces, Esc, RTS and Retail'!$D:$F,3,0) -> #N/A | AL20: =VLOOKUP(B20,'Ces, Esc, RTS and Retail'!$H:$H,1,0) -> #N/A | AM20: =VLOOKUP(Q20,'Ces, Esc, RTS and Retail'!$J:$J,1,0) -> #N/A | AN20: =VLOOKUP(Q20,'[2]Trip Manager Report(Updated)_V2'!$I:$Z,18,0) -> #N/A | AO20: =VLOOKUP(E20,'Ces, Esc, RTS and Retail'!$L:$L,1,0) -> #N/A | AP20: =VLOOKUP(Q20,Response!$H:$M,5,0) -> #N/A
A21: Wakefit | B21: ORDER202605ldgHkv | C21: Anvith Hegde | D21: No 16, 1, Cox Town, Home well towers sun | E21: 560005 | F21: 7676171571 | G21: 7676171571 | H21: WTVUHEIST | J21: furniture | K21: 1007000862 | L21: Tv Unit | M21: FG01 | N21: 1 | O21: COD | P21: 26050590016893 | Q21: WFFI448097 | R21: BLR LOCAL | S21: Normal Order | T21: Shipped | U21: 2026-05-24 | V21: 2026-05-24 | W21: 2026-06-07 | X21: 2026-06-08 | Y21: 2026-05-30T20:11:04 | Z21: 2026-06-13T20:23:27 | AA21: Breached | AB21: 0 | AD21: =VLOOKUP(Q21,'[1]an1asv_22-06-2026_06-23-43'!$B:$OA,3,0) -> reachedathub | AE21: =VLOOKUP(Q21,'[1]an1asv_22-06-2026_06-23-43'!$B:$OA,147,0) -> CNR/ No Date from Customer | AF21: =VLOOKUP(Q21,'[1]an1asv_22-06-2026_06-23-43'!$B:$OA,48,0) -> 46196 | AG21: =VLOOKUP(F21,Response!$A:$B,2,0) -> #N/A | AH21: CNR | AJ21: =VLOOKUP(B21,'Ces, Esc, RTS and Retail'!$A:$B,2,0) -> #N/A | AK21: =VLOOKUP(F21,'Ces, Esc, RTS and Retail'!$D:$F,3,0) -> #N/A | AL21: =VLOOKUP(B21,'Ces, Esc, RTS and Retail'!$H:$H,1,0) -> #N/A | AM21: =VLOOKUP(Q21,'Ces, Esc, RTS and Retail'!$J:$J,1,0) -> #N/A | AN21: =VLOOKUP(Q21,'[2]Trip Manager Report(Updated)_V2'!$I:$Z,18,0) -> #N/A | AO21: =VLOOKUP(E21,'Ces, Esc, RTS and Retail'!$L:$L,1,0) -> #N/A | AP21: =VLOOKUP(Q21,Response!$H:$M,5,0) -> #N/A
A22: Wakefit_Retail | B22: ORDER202603o3FbHd | C22: ABHISHEK SHARMA | D22: Comfort Aanandaranga, Flat 101, First Floor, No. 12, 1st cross road, Srinivas Colony, Sudhamnagar,Bengaluru | E22: 560027 | F22: 8147713806 | G22: 8147115142 | H22: WMDINESLMORS6AB | J22: furniture | K22: 1001026208 | L22: Metal Dining Table | M22: FG01 | N22: 1 | O22: ONLINE | P22: 26060590002271 | Q22: WFFI451420 | R22: BLR LOCAL | S22: Normal Order | T22: Shipped | U22: 2026-03-22 | V22: 2026-05-24 | W22: 2026-06-22 | X22: 2026-06-22 | Y22: 2026-06-05T07:04:49 | Z22: 2026-06-14T20:08:49 | AA22: Breached | AB22: 0 | AD22: =VLOOKUP(Q22,'[1]an1asv_22-06-2026_06-23-43'!$B:$OA,3,0) -> reachedathub | AE22: =VLOOKUP(Q22,'[1]an1asv_22-06-2026_06-23-43'!$B:$OA,147,0) -> Customer Request for Future Date Delivery | AF22: =VLOOKUP(Q22,'[1]an1asv_22-06-2026_06-23-43'!$B:$OA,48,0) -> 46205 | AG22: =VLOOKUP(F22,Response!$A:$B,2,0) -> #N/A | AH22: CFR | AI22: =AF22 -> 46205 | AJ22: =VLOOKUP(B22,'Ces, Esc, RTS and Retail'!$A:$B,2,0) -> #N/A | AK22: =VLOOKUP(F22,'Ces, Esc, RTS and Retail'!$D:$F,3,0) -> #N/A | AL22: =VLOOKUP(B22,'Ces, Esc, RTS and Retail'!$H:$H,1,0) -> #N/A | AM22: =VLOOKUP(Q22,'Ces, Esc, RTS and Retail'!$J:$J,1,0) -> #N/A | AN22: =VLOOKUP(Q22,'[2]Trip Manager Report(Updated)_V2'!$I:$Z,18,0) -> #N/A | AO22: =VLOOKUP(E22,'Ces, Esc, RTS and Retail'!$L:$L,1,0) -> #N/A | AP22: =VLOOKUP(Q22,Response!$H:$M,5,0) -> #N/A
A23: Wakefit_Retail | B23: ORDER202603o3FbHd | C23: ABHISHEK SHARMA | D23: Comfort Aanandaranga, Flat 101, First Floor, No. 12, 1st cross road, Srinivas Colony, Sudhamnagar,Bengaluru | E23: 560027 | F23: 8147713806 | G23: 8147115142 | H23: WMCFTPRANGRCOB | J23: furniture | K23: 1007103227 | L23: Metal Coffee Table | M23: FG01 | N23: 1 | O23: ONLINE | P23: 26060590001211 | Q23: WFFWI216269 | R23: BLR LOCAL | S23: Normal Order | T23: Shipped | U23: 2026-03-22 | V23: 2026-05-24 | W23: 2026-06-22 | X23: 2026-06-22 | Y23: 2026-06-02T22:04:00 | Z23: 2026-06-14T20:08:49 | AA23: Breached | AB23: 0 | AD23: =VLOOKUP(Q23,'[1]an1asv_22-06-2026_06-23-43'!$B:$OA,3,0) -> reachedathub | AE23: =VLOOKUP(Q23,'[1]an1asv_22-06-2026_06-23-43'!$B:$OA,147,0) -> Customer Request for Future Date Delivery | AF23: =VLOOKUP(Q23,'[1]an1asv_22-06-2026_06-23-43'!$B:$OA,48,0) -> 46205 | AG23: =VLOOKUP(F23,Response!$A:$B,2,0) -> #N/A | AH23: CFR | AI23: =AF23 -> 46205 | AJ23: =VLOOKUP(B23,'Ces, Esc, RTS and Retail'!$A:$B,2,0) -> #N/A | AK23: =VLOOKUP(F23,'Ces, Esc, RTS and Retail'!$D:$F,3,0) -> #N/A | AL23: =VLOOKUP(B23,'Ces, Esc, RTS and Retail'!$H:$H,1,0) -> #N/A | AM23: =VLOOKUP(Q23,'Ces, Esc, RTS and Retail'!$J:$J,1,0) -> #N/A | AN23: =VLOOKUP(Q23,'[2]Trip Manager Report(Updated)_V2'!$I:$Z,18,0) -> #N/A | AO23: =VLOOKUP(E23,'Ces, Esc, RTS and Retail'!$L:$L,1,0) -> #N/A | AP23: =VLOOKUP(Q23,Response!$H:$M,5,0) -> #N/A
A24: Wakefit_Retail | B24: ORDER202605AGEQsN | C24: Prakash Puvvada | D24: Flat No 118 1st floor PSR AUSTIN APARTMENT, Hosahalli Road, Sompura gate | E24: 562125 | F24: 8106964687 | H24: WEWB7860HYSTESSERCW | I24: 78x60 inch | J24: furniture | K24: 1001033590 | L24: Engineered Wood Bed | M24: FG01 | N24: 1 | O24: ONLINE | P24: 26060590009829 | Q24: WFFI459779 | R24: BLR LOCAL | S24: Normal Order | T24: Shipped | U24: 2026-05-24 | V24: 2026-05-24 | W24: 2026-06-21 | X24: 2026-06-22 | Y24: 2026-06-19T22:21:54 | Z24: 2026-06-20T22:09:12 | AA24: Breached | AB24: 0 | AD24: =VLOOKUP(Q24,'[1]an1asv_22-06-2026_06-23-43'!$B:$OA,3,0) -> reachedathub | AE24: =VLOOKUP(Q24,'[1]an1asv_22-06-2026_06-23-43'!$B:$OA,147,0) -> Planned | AF24: =VLOOKUP(Q24,'[1]an1asv_22-06-2026_06-23-43'!$B:$OA,48,0) -> 46195 | AG24: =VLOOKUP(F24,Response!$A:$B,2,0) -> #N/A | AH24: Planned | AJ24: =VLOOKUP(B24,'Ces, Esc, RTS and Retail'!$A:$B,2,0) -> #N/A | AK24: =VLOOKUP(F24,'Ces, Esc, RTS and Retail'!$D:$F,3,0) -> #N/A | AL24: =VLOOKUP(B24,'Ces, Esc, RTS and Retail'!$H:$H,1,0) -> #N/A | AM24: =VLOOKUP(Q24,'Ces, Esc, RTS and Retail'!$J:$J,1,0) -> #N/A | AN24: =VLOOKUP(Q24,'[2]Trip Manager Report(Updated)_V2'!$I:$Z,18,0) -> INSUFFICIENT TIME | AO24: =VLOOKUP(E24,'Ces, Esc, RTS and Retail'!$L:$L,1,0) -> #N/A | AP24: =VLOOKUP(Q24,Response!$H:$M,5,0) -> #N/A
A25: Wakefit_Retail | B25: ORDER202605Mmtvak | C25: chandan GS | D25: #35, 1 st floor 17 th cross muthyalanagar Near DC golden lotus Apartment Benaglauru 560054 | E25: 560054 | F25: 7353939151 | G25: 9739915331 | H25: WEWB7872HYSTESSERCW | I25: 78x72 inch | J25: furniture | K25: 1001033589 | L25: Engineered Wood Bed | M25: FG01 | N25: 1 | O25: ONLINE | P25: 26060590009793 | Q25: WFFI459752 | R25: BLR LOCAL | S25: Normal Order | T25: Shipped | U25: 2026-05-24 | V25: 2026-05-24 | W25: 2026-06-21 | X25: 2026-06-22 | Y25: 2026-06-19T22:21:14 | Z25: 2026-06-20T20:45:33 | AA25: Breached | AB25: 0 | AD25: =VLOOKUP(Q25,'[1]an1asv_22-06-2026_06-23-43'!$B:$OA,3,0) -> reachedathub | AE25: =VLOOKUP(Q25,'[1]an1asv_22-06-2026_06-23-43'!$B:$OA,147,0) -> CUSTOMER FUTURE REQUEST | AF25: =VLOOKUP(Q25,'[1]an1asv_22-06-2026_06-23-43'!$B:$OA,48,0) -> 46195 | AG25: =VLOOKUP(F25,Response!$A:$B,2,0) -> 1 | AH25: Planned | AJ25: =VLOOKUP(B25,'Ces, Esc, RTS and Retail'!$A:$B,2,0) -> #N/A | AK25: =VLOOKUP(F25,'Ces, Esc, RTS and Retail'!$D:$F,3,0) -> #N/A | AL25: =VLOOKUP(B25,'Ces, Esc, RTS and Retail'!$H:$H,1,0) -> #N/A | AM25: =VLOOKUP(Q25,'Ces, Esc, RTS and Retail'!$J:$J,1,0) -> #N/A | AN25: =VLOOKUP(Q25,'[2]Trip Manager Report(Updated)_V2'!$I:$Z,18,0) -> CUSTOMER FUTURE REQUEST | AO25: =VLOOKUP(E25,'Ces, Esc, RTS and Retail'!$L:$L,1,0) -> #N/A | AP25: =VLOOKUP(Q25,Response!$H:$M,5,0) -> #N/A
A26: Wakefit_Retail | B26: ORDER202605zaSW72 | C26: Sourabh JAIN | D26: B019, Ground Floor, Samhita Greenwoods, Thubarahalli, Bangalore, Karnataka | E26: 560066 | F26: 8553246986 | H26: WEWB7860HYSUPOGRTAURUSR4 | I26: 78x60 inch | J26: furniture | K26: 1007003128 | L26: Engineered Wood Bed | M26: FG01 | N26: 1 | O26: ONLINE | P26: 26050590015502 | Q26: WFFI446325 | R26: BLR LOCAL | S26: Normal Order | T26: Shipped | U26: 2026-05-24 | V26: 2026-05-24 | W26: 2026-06-06 | X26: 2026-06-07 | Y26: 2026-05-28T09:41:39 | Z26: 2026-06-06T21:44:57 | AA26: Breached | AB26: 0 | AD26: =VLOOKUP(Q26,'[1]an1asv_22-06-2026_06-23-43'!$B:$OA,3,0) -> reachedathub | AE26: =VLOOKUP(Q26,'[1]an1asv_22-06-2026_06-23-43'!$B:$OA,147,0) -> Customer Request for Future Date Delivery | AF26: =VLOOKUP(Q26,'[1]an1asv_22-06-2026_06-23-43'!$B:$OA,48,0) -> 46208 | AG26: =VLOOKUP(F26,Response!$A:$B,2,0) -> #N/A | AH26: CFR | AI26: =AF26 -> 46208 | AJ26: =VLOOKUP(B26,'Ces, Esc, RTS and Retail'!$A:$B,2,0) -> #N/A | AK26: =VLOOKUP(F26,'Ces, Esc, RTS and Retail'!$D:$F,3,0) -> #N/A | AL26: =VLOOKUP(B26,'Ces, Esc, RTS and Retail'!$H:$H,1,0) -> #N/A | AM26: =VLOOKUP(Q26,'Ces, Esc, RTS and Retail'!$J:$J,1,0) -> #N/A | AN26: =VLOOKUP(Q26,'[2]Trip Manager Report(Updated)_V2'!$I:$Z,18,0) -> #N/A | AO26: =VLOOKUP(E26,'Ces, Esc, RTS and Retail'!$L:$L,1,0) -> #N/A | AP26: =VLOOKUP(Q26,Response!$H:$M,5,0) -> #N/A
A27: Wakefit | B27: ORDER202605MPY3Dx | C27: Yogesh Mallik | D27: C305, 3, TVS Emerald Jardin, Manipal County Road | E27: 560068 | F27: 7676187519 | G27: 7676187519 | H27: WEWB7860HYSHALOSFW | I27: 78x60 inch | J27: furniture | K27: 1001033493 | L27: Engineered Wood Bed | M27: FG01 | N27: 1 | O27: ONLINE | P27: 26060590001218 | Q27: WFFI449914 | R27: BLR LOCAL | S27: Normal Order | T27: Docketed | U27: 2026-05-25 | V27: 2026-05-25 | W27: 2026-06-21 | X27: 2026-06-22 | Y27: 2026-06-02T22:04:10 | AA27: Breached | AB27: 0 | AD27: =VLOOKUP(Q27,'[1]an1asv_22-06-2026_06-23-43'!$B:$OA,3,0) -> reachedathub | AE27: =VLOOKUP(Q27,'[1]an1asv_22-06-2026_06-23-43'!$B:$OA,147,0) -> Customer Request for Future Date Delivery | AF27: =VLOOKUP(Q27,'[1]an1asv_22-06-2026_06-23-43'!$B:$OA,48,0) -> 46197 | AG27: =VLOOKUP(F27,Response!$A:$B,2,0) -> #N/A | AH27: CFR | AI27: =AF27 -> 46197 | AJ27: =VLOOKUP(B27,'Ces, Esc, RTS and Retail'!$A:$B,2,0) -> #N/A | AK27: =VLOOKUP(F27,'Ces, Esc, RTS and Retail'!$D:$F,3,0) -> 46197 | AL27: =VLOOKUP(B27,'Ces, Esc, RTS and Retail'!$H:$H,1,0) -> #N/A | AM27: =VLOOKUP(Q27,'Ces, Esc, RTS and Retail'!$J:$J,1,0) -> #N/A | AN27: =VLOOKUP(Q27,'[2]Trip Manager Report(Updated)_V2'!$I:$Z,18,0) -> #N/A | AO27: =VLOOKUP(E27,'Ces, Esc, RTS and Retail'!$L:$L,1,0) -> #N/A | AP27: =VLOOKUP(Q27,Response!$H:$M,5,0) -> #N/A
A28: Wakefit_Retail | B28: ORDER202605qUUGPK | C28: Raghavendra | D28: No 86 Channenahalli magadi main road pipeline road | E28: 562130 | F28: 9844564837 | G28: 9620123412 | H28: WWRB3S4D2MH2SH3TYRIANPPB | J28: furniture | K28: 1001029025 | L28: Wardrobes | M28: FG01 | N28: 1 | O28: ONLINE | P28: 26060590010658 | Q28: WFFI460885 | R28: BLR LOCAL | S28: Normal Order | T28: Docketed | U28: 2026-05-25 | V28: 2026-05-25 | W28: 2026-06-21 | X28: 2026-06-25 | Y28: 2026-06-22T09:36:02 | AA28: P1 | AB28: 0 | AD28: =VLOOKUP(Q28,'[1]an1asv_22-06-2026_06-23-43'!$B:$OA,3,0) -> reachedathub | AE28: =VLOOKUP(Q28,'[1]an1asv_22-06-2026_06-23-43'!$B:$OA,147,0) -> 0 | AF28: =VLOOKUP(Q28,'[1]an1asv_22-06-2026_06-23-43'!$B:$OA,48,0) -> 46195 | AG28: =VLOOKUP(F28,Response!$A:$B,2,0) -> #N/A | AH28: Outside Service Location | AJ28: =VLOOKUP(B28,'Ces, Esc, RTS and Retail'!$A:$B,2,0) -> #N/A | AK28: =VLOOKUP(F28,'Ces, Esc, RTS and Retail'!$D:$F,3,0) -> #N/A | AL28: =VLOOKUP(B28,'Ces, Esc, RTS and Retail'!$H:$H,1,0) -> #N/A | AM28: =VLOOKUP(Q28,'Ces, Esc, RTS and Retail'!$J:$J,1,0) -> #N/A | AN28: =VLOOKUP(Q28,'[2]Trip Manager Report(Updated)_V2'!$I:$Z,18,0) -> #N/A | AO28: =VLOOKUP(E28,'Ces, Esc, RTS and Retail'!$L:$L,1,0) -> 562130 | AP28: =VLOOKUP(Q28,Response!$H:$M,5,0) -> #N/A
A29: Wakefit_Retail | B29: ORDER202605mSiBNx | C29: Tony Pius | D29: No 77/38 1st main 11th cross Bharathi Layout SG Palya | E29: 560029 | F29: 9844142957 | H29: WEWB7860STESSERCW | I29: 78x60 inch | J29: furniture | K29: 1001033592 | L29: Engineered Wood Bed | M29: FG01 | N29: 1 | O29: ONLINE | P29: 26060590010669 | Q29: WFFI460896 | R29: BLR LOCAL | S29: Normal Order | T29: Docketed | U29: 2026-05-25 | V29: 2026-05-25 | W29: 2026-06-21 | X29: 2026-06-22 | Y29: 2026-06-22T09:36:22 | AA29: Breached | AB29: 0 | AD29: =VLOOKUP(Q29,'[1]an1asv_22-06-2026_06-23-43'!$B:$OA,3,0) -> reachedathub | AE29: =VLOOKUP(Q29,'[1]an1asv_22-06-2026_06-23-43'!$B:$OA,147,0) -> 0 | AF29: =VLOOKUP(Q29,'[1]an1asv_22-06-2026_06-23-43'!$B:$OA,48,0) -> 46195 | AG29: =VLOOKUP(F29,Response!$A:$B,2,0) -> #N/A | AH29: CNR | AJ29: =VLOOKUP(B29,'Ces, Esc, RTS and Retail'!$A:$B,2,0) -> #N/A | AK29: =VLOOKUP(F29,'Ces, Esc, RTS and Retail'!$D:$F,3,0) -> #N/A | AL29: =VLOOKUP(B29,'Ces, Esc, RTS and Retail'!$H:$H,1,0) -> #N/A | AM29: =VLOOKUP(Q29,'Ces, Esc, RTS and Retail'!$J:$J,1,0) -> #N/A | AN29: =VLOOKUP(Q29,'[2]Trip Manager Report(Updated)_V2'!$I:$Z,18,0) -> #N/A | AO29: =VLOOKUP(E29,'Ces, Esc, RTS and Retail'!$L:$L,1,0) -> #N/A | AP29: =VLOOKUP(Q29,Response!$H:$M,5,0) -> #N/A
A30: Amazon | B30: 406-2931917-2985941 | C30: Sushant Mishra | D30: Munnekolal, Marathali Jaipur roti point building, 3rd floor , flat number C9 | E30: 560037 | F30: 8240196250 | H30: WWRB2DMH1GINGHAMUTR2 | J30: furniture | K30: 1007129110 | L30: Wardrobes | M30: FG01 | N30: 1 | O30: ONLINE | P30: 26060590009240 | Q30: WFFI458997 | R30: BLR LOCAL | S30: Normal Order | T30: Shipped | U30: 2026-05-25 | V30: 2026-05-25 | W30: 2026-06-16 | X30: 2026-06-22 | Y30: 2026-06-18T17:35:59 | Z30: 2026-06-20T19:28:47 | AA30: Breached | AB30: 0 | AD30: =VLOOKUP(Q30,'[1]an1asv_22-06-2026_06-23-43'!$B:$OA,3,0) -> reachedathub | AE30: =VLOOKUP(Q30,'[1]an1asv_22-06-2026_06-23-43'!$B:$OA,147,0) -> Planned | AF30: =VLOOKUP(Q30,'[1]an1asv_22-06-2026_06-23-43'!$B:$OA,48,0) -> 46195 | AG30: =VLOOKUP(F30,Response!$A:$B,2,0) -> #N/A | AH30: CNR | AJ30: =VLOOKUP(B30,'Ces, Esc, RTS and Retail'!$A:$B,2,0) -> #N/A | AK30: =VLOOKUP(F30,'Ces, Esc, RTS and Retail'!$D:$F,3,0) -> #N/A | AL30: =VLOOKUP(B30,'Ces, Esc, RTS and Retail'!$H:$H,1,0) -> #N/A | AM30: =VLOOKUP(Q30,'Ces, Esc, RTS and Retail'!$J:$J,1,0) -> #N/A | AN30: =VLOOKUP(Q30,'[2]Trip Manager Report(Updated)_V2'!$I:$Z,18,0) -> CUSTOMER NOT REACHABLE | AO30: =VLOOKUP(E30,'Ces, Esc, RTS and Retail'!$L:$L,1,0) -> #N/A | AP30: =VLOOKUP(Q30,Response!$H:$M,5,0) -> #N/A
A31: Amazon | B31: 408-7252058-8797147 | C31: Surabhi Sheshadri | D31: 106, Salarpuria Cambridge residency Ulsoor | E31: 560008 | F31: 9819393551 | H31: WWRB3TWILLDBR2 | J31: furniture | K31: 1007124269 | L31: Wardrobes | M31: FG01 | N31: 1 | O31: ONLINE | P31: 26060590002389 | Q31: WFFI451529 | R31: BLR LOCAL | S31: Normal Order | T31: Docketed | U31: 2026-05-26 | V31: 2026-05-26 | W31: 2026-06-17 | X31: 2026-06-23 | Y31: 2026-06-05T12:55:58 | AA31: Breached | AB31: 0 | AD31: =VLOOKUP(Q31,'[1]an1asv_22-06-2026_06-23-43'!$B:$OA,3,0) -> reachedathub | AE31: =VLOOKUP(Q31,'[1]an1asv_22-06-2026_06-23-43'!$B:$OA,147,0) -> CNR/ No Date from Customer | AF31: =VLOOKUP(Q31,'[1]an1asv_22-06-2026_06-23-43'!$B:$OA,48,0) -> 46196 | AG31: =VLOOKUP(F31,Response!$A:$B,2,0) -> #N/A | AH31: CNR | AJ31: =VLOOKUP(B31,'Ces, Esc, RTS and Retail'!$A:$B,2,0) -> #N/A | AK31: =VLOOKUP(F31,'Ces, Esc, RTS and Retail'!$D:$F,3,0) -> #N/A | AL31: =VLOOKUP(B31,'Ces, Esc, RTS and Retail'!$H:$H,1,0) -> #N/A | AM31: =VLOOKUP(Q31,'Ces, Esc, RTS and Retail'!$J:$J,1,0) -> #N/A | AN31: =VLOOKUP(Q31,'[2]Trip Manager Report(Updated)_V2'!$I:$Z,18,0) -> #N/A | AO31: =VLOOKUP(E31,'Ces, Esc, RTS and Retail'!$L:$L,1,0) -> #N/A | AP31: =VLOOKUP(Q31,Response!$H:$M,5,0) -> 0
A32: Wakefit_Retail | B32: ORDER202603PbfafE | C32: NAWAL KISHORE LODHA | D32: VILLA NO 134 PRESTIGE SILVER OAK ECC ROAD WHITEFIELD | E32: 560066 | F32: 9972512512 | H32: WEWB7860HYSRUBBLE | I32: 78x60 inch | J32: furniture | K32: 1001021918 | L32: Engineered Wood Bed | M32: FG01 | N32: 1 | O32: ONLINE | P32: 26060590010217 | Q32: WFFI460440 | R32: BLR LOCAL | S32: Replacement | T32: Docketed | U32: 2026-05-26 | V32: 2026-05-26 | W32: 2026-06-21 | X32: 2026-06-22 | Y32: 2026-06-21T11:41:14 | AA32: Breached | AB32: 0 | AD32: =VLOOKUP(Q32,'[1]an1asv_22-06-2026_06-23-43'!$B:$OA,3,0) -> reachedathub | AE32: =VLOOKUP(Q32,'[1]an1asv_22-06-2026_06-23-43'!$B:$OA,147,0) -> 0 | AF32: =VLOOKUP(Q32,'[1]an1asv_22-06-2026_06-23-43'!$B:$OA,48,0) -> 46195 | AG32: =VLOOKUP(F32,Response!$A:$B,2,0) -> #N/A | AH32: CNR | AJ32: =VLOOKUP(B32,'Ces, Esc, RTS and Retail'!$A:$B,2,0) -> #N/A | AK32: =VLOOKUP(F32,'Ces, Esc, RTS and Retail'!$D:$F,3,0) -> #N/A | AL32: =VLOOKUP(B32,'Ces, Esc, RTS and Retail'!$H:$H,1,0) -> #N/A | AM32: =VLOOKUP(Q32,'Ces, Esc, RTS and Retail'!$J:$J,1,0) -> #N/A | AN32: =VLOOKUP(Q32,'[2]Trip Manager Report(Updated)_V2'!$I:$Z,18,0) -> #N/A | AO32: =VLOOKUP(E32,'Ces, Esc, RTS and Retail'!$L:$L,1,0) -> #N/A | AP32: =VLOOKUP(Q32,Response!$H:$M,5,0) -> #N/A
A33: Wakefit_Retail | B33: ORDER202605dyR4zG | C33: divya | D33: #68,Arihant Castle Apartment Flat no 301, 4th floor , shankarmutt main road bangalore - 560004 | E33: 560004 | F33: 9902362000 | H33: WCFTJAVA | J33: furniture | K33: 1003010011 | L33: Coffee Table | M33: FG01 | N33: 1 | O33: PREPAID-CASH | P33: 26060590010661 | Q33: WFFI460880 | R33: BLR LOCAL | S33: Normal Order | T33: Docketed | U33: 2026-05-26 | V33: 2026-05-26 | W33: 2026-06-21 | X33: 2026-06-22 | Y33: 2026-06-22T09:36:01 | AA33: Breached | AB33: 0 | AD33: =VLOOKUP(Q33,'[1]an1asv_22-06-2026_06-23-43'!$B:$OA,3,0) -> reachedathub | AE33: =VLOOKUP(Q33,'[1]an1asv_22-06-2026_06-23-43'!$B:$OA,147,0) -> 0 | AF33: =VLOOKUP(Q33,'[1]an1asv_22-06-2026_06-23-43'!$B:$OA,48,0) -> 46195 | AG33: =VLOOKUP(F33,Response!$A:$B,2,0) -> #N/A | AH33: CNR | AJ33: =VLOOKUP(B33,'Ces, Esc, RTS and Retail'!$A:$B,2,0) -> #N/A | AK33: =VLOOKUP(F33,'Ces, Esc, RTS and Retail'!$D:$F,3,0) -> #N/A | AL33: =VLOOKUP(B33,'Ces, Esc, RTS and Retail'!$H:$H,1,0) -> #N/A | AM33: =VLOOKUP(Q33,'Ces, Esc, RTS and Retail'!$J:$J,1,0) -> #N/A | AN33: =VLOOKUP(Q33,'[2]Trip Manager Report(Updated)_V2'!$I:$Z,18,0) -> #N/A | AO33: =VLOOKUP(E33,'Ces, Esc, RTS and Retail'!$L:$L,1,0) -> #N/A | AP33: =VLOOKUP(Q33,Response!$H:$M,5,0) -> #N/A
A34: Wakefit | B34: ORDER202605TdKrU4 | C34: David Anand | D34: 3, 44, Bethel house, 1st A Cross, BDS Layout, RK Hegde Nagar | E34: 560077 | F34: 9353561311 | G34: 9788925253 | H34: WWRB3TWILLCW | J34: furniture | K34: 1007100259 | L34: Wardrobes | M34: FG01 | N34: 1 | O34: ONLINE | P34: 26060590010263 | Q34: WFFI460481 | R34: BLR LOCAL | S34: Normal Order | T34: Docketed | U34: 2026-05-27 | V34: 2026-05-27 | W34: 2026-06-22 | X34: 2026-06-23 | Y34: 2026-06-21T11:42:23 | AA34: Breached | AB34: 0 | AD34: =VLOOKUP(Q34,'[1]an1asv_22-06-2026_06-23-43'!$B:$OA,3,0) -> reachedathub | AE34: =VLOOKUP(Q34,'[1]an1asv_22-06-2026_06-23-43'!$B:$OA,147,0) -> 0 | AF34: =VLOOKUP(Q34,'[1]an1asv_22-06-2026_06-23-43'!$B:$OA,48,0) -> 46195 | AG34: =VLOOKUP(F34,Response!$A:$B,2,0) -> #N/A | AH34: Planned | AJ34: =VLOOKUP(B34,'Ces, Esc, RTS and Retail'!$A:$B,2,0) -> #N/A | AK34: =VLOOKUP(F34,'Ces, Esc, RTS and Retail'!$D:$F,3,0) -> #N/A | AL34: =VLOOKUP(B34,'Ces, Esc, RTS and Retail'!$H:$H,1,0) -> #N/A | AM34: =VLOOKUP(Q34,'Ces, Esc, RTS and Retail'!$J:$J,1,0) -> #N/A | AN34: =VLOOKUP(Q34,'[2]Trip Manager Report(Updated)_V2'!$I:$Z,18,0) -> #N/A | AO34: =VLOOKUP(E34,'Ces, Esc, RTS and Retail'!$L:$L,1,0) -> #N/A | AP34: =VLOOKUP(Q34,Response!$H:$M,5,0) -> Yes
A35: Wakefit_Retail | B35: ORDER202605epfvW6 | C35: Paul Daniel | D35: 88/1, 2nd Floor, 7th Cross Rd, Athmananda Colony, RT Nagar, Bangalore - 560032 | E35: 560032 | F35: 8553736540 | G35: 8861042648 | H35: WSWB7860TIERHBTW | I35: 78x60 inch | J35: furniture | K35: 1007129571 | L35: Cot | M35: FG01 | N35: 1 | O35: ONLINE | P35: 26060590008892 | Q35: WFFI458515 | R35: BLR LOCAL | S35: Normal Order | T35: Shipped | U35: 2026-05-27 | V35: 2026-05-27 | W35: 2026-06-21 | X35: 2026-06-22 | Y35: 2026-06-18T09:06:10 | Z35: 2026-06-20T19:24:25 | AA35: Breached | AB35: 0 | AD35: =VLOOKUP(Q35,'[1]an1asv_22-06-2026_06-23-43'!$B:$OA,3,0) -> reachedathub | AE35: =VLOOKUP(Q35,'[1]an1asv_22-06-2026_06-23-43'!$B:$OA,147,0) -> Planned | AF35: =VLOOKUP(Q35,'[1]an1asv_22-06-2026_06-23-43'!$B:$OA,48,0) -> 46195 | AG35: =VLOOKUP(F35,Response!$A:$B,2,0) -> #N/A | AH35: CNR | AJ35: =VLOOKUP(B35,'Ces, Esc, RTS and Retail'!$A:$B,2,0) -> #N/A | AK35: =VLOOKUP(F35,'Ces, Esc, RTS and Retail'!$D:$F,3,0) -> #N/A | AL35: =VLOOKUP(B35,'Ces, Esc, RTS and Retail'!$H:$H,1,0) -> #N/A | AM35: =VLOOKUP(Q35,'Ces, Esc, RTS and Retail'!$J:$J,1,0) -> #N/A | AN35: =VLOOKUP(Q35,'[2]Trip Manager Report(Updated)_V2'!$I:$Z,18,0) -> CUSTOMER FUTURE REQUEST | AO35: =VLOOKUP(E35,'Ces, Esc, RTS and Retail'!$L:$L,1,0) -> #N/A | AP35: =VLOOKUP(Q35,Response!$H:$M,5,0) -> #N/A
A36: Wakefit | B36: ORDER202605IDlpYb | C36: Harish J | D36: No 235, VASISHTA, 9th Cross, Bapuji Layout, Vijayanagar, Bengaluru | E36: 560040 | F36: 9449262840 | G36: 9449262840 | H36: WWRB3TWILLDBR2 | J36: furniture | K36: 1007124269 | L36: Wardrobes | M36: FG01 | N36: 1 | O36: ONLINE | P36: 26060590002759 | Q36: WFFI451733 | R36: BLR LOCAL | S36: Normal Order | T36: Shipped | U36: 2026-05-27 | V36: 2026-05-27 | W36: 2026-06-24 | X36: 2026-06-25 | Y36: 2026-06-05T21:15:31 | Z36: 2026-06-21T21:07:41 | AA36: P1 | AB36: 0 | AD36: =VLOOKUP(Q36,'[1]an1asv_22-06-2026_06-23-43'!$B:$OA,3,0) -> reachedathub | AE36: =VLOOKUP(Q36,'[1]an1asv_22-06-2026_06-23-43'!$B:$OA,147,0) -> CNR/ No Date from Customer | AF36: =VLOOKUP(Q36,'[1]an1asv_22-06-2026_06-23-43'!$B:$OA,48,0) -> 46196 | AG36: =VLOOKUP(F36,Response!$A:$B,2,0) -> #N/A | AH36: Capcity Filled-Not Called | AJ36: =VLOOKUP(B36,'Ces, Esc, RTS and Retail'!$A:$B,2,0) -> #N/A | AK36: =VLOOKUP(F36,'Ces, Esc, RTS and Retail'!$D:$F,3,0) -> #N/A | AL36: =VLOOKUP(B36,'Ces, Esc, RTS and Retail'!$H:$H,1,0) -> #N/A | AM36: =VLOOKUP(Q36,'Ces, Esc, RTS and Retail'!$J:$J,1,0) -> #N/A | AN36: =VLOOKUP(Q36,'[2]Trip Manager Report(Updated)_V2'!$I:$Z,18,0) -> #N/A | AO36: =VLOOKUP(E36,'Ces, Esc, RTS and Retail'!$L:$L,1,0) -> #N/A | AP36: =VLOOKUP(Q36,Response!$H:$M,5,0) -> #N/A
A37: Wakefit | B37: ORDER202605XvXy8i | C37: Pooja | D37: Tower1-302, 3, Sattva Divinity, 9th cross, Pantharapalya, Nayandahalli, Bengaluru | E37: 560026 | F37: 9449262840 | G37: 8861848692 | H37: WWRB3TWILLCW | J37: furniture | K37: 1007100259 | L37: Wardrobes | M37: FG01 | N37: 1 | O37: ONLINE | P37: 26060590010259 | Q37: WFFI460479 | R37: BLR LOCAL | S37: Normal Order | T37: Docketed | U37: 2026-05-28 | V37: 2026-05-28 | W37: 2026-06-22 | X37: 2026-06-23 | Y37: 2026-06-21T11:42:14 | AA37: Breached | AB37: 0 | AD37: =VLOOKUP(Q37,'[1]an1asv_22-06-2026_06-23-43'!$B:$OA,3,0) -> reachedathub | AE37: =VLOOKUP(Q37,'[1]an1asv_22-06-2026_06-23-43'!$B:$OA,147,0) -> 0 | AF37: =VLOOKUP(Q37,'[1]an1asv_22-06-2026_06-23-43'!$B:$OA,48,0) -> 46195 | AG37: =VLOOKUP(F37,Response!$A:$B,2,0) -> #N/A | AH37: CNR | AJ37: =VLOOKUP(B37,'Ces, Esc, RTS and Retail'!$A:$B,2,0) -> #N/A | AK37: =VLOOKUP(F37,'Ces, Esc, RTS and Retail'!$D:$F,3,0) -> #N/A | AL37: =VLOOKUP(B37,'Ces, Esc, RTS and Retail'!$H:$H,1,0) -> #N/A | AM37: =VLOOKUP(Q37,'Ces, Esc, RTS and Retail'!$J:$J,1,0) -> #N/A | AN37: =VLOOKUP(Q37,'[2]Trip Manager Report(Updated)_V2'!$I:$Z,18,0) -> #N/A | AO37: =VLOOKUP(E37,'Ces, Esc, RTS and Retail'!$L:$L,1,0) -> #N/A | AP37: =VLOOKUP(Q37,Response!$H:$M,5,0) -> 0
A38: Wakefit | B38: ORDER2026053qD8Zl | C38: Yogesh Bhavsar | D38: A-405, 4, Mana Candela - 2, Kodathi, Sarjapur Road, Behind Wipro Sez. | E38: 560035 | F38: 9662160875 | G38: 9662160875 | H38: WEWB7872SASTRA | I38: 78x72 inch | J38: furniture | K38: 1007100292 | L38: Engineered Wood Bed | M38: FG01 | N38: 1 | O38: ONLINE | P38: 26060590010660 | Q38: WFFI460883 | R38: BLR LOCAL | S38: Normal Order | T38: Docketed | U38: 2026-05-28 | V38: 2026-05-28 | W38: 2026-06-21 | X38: 2026-06-22 | Y38: 2026-06-22T09:36:01 | AA38: Breached | AB38: 0 | AD38: =VLOOKUP(Q38,'[1]an1asv_22-06-2026_06-23-43'!$B:$OA,3,0) -> reachedathub | AE38: =VLOOKUP(Q38,'[1]an1asv_22-06-2026_06-23-43'!$B:$OA,147,0) -> 0 | AF38: =VLOOKUP(Q38,'[1]an1asv_22-06-2026_06-23-43'!$B:$OA,48,0) -> 46195 | AG38: =VLOOKUP(F38,Response!$A:$B,2,0) -> 1 | AH38: Planned | AJ38: =VLOOKUP(B38,'Ces, Esc, RTS and Retail'!$A:$B,2,0) -> #N/A | AK38: =VLOOKUP(F38,'Ces, Esc, RTS and Retail'!$D:$F,3,0) -> #N/A | AL38: =VLOOKUP(B38,'Ces, Esc, RTS and Retail'!$H:$H,1,0) -> #N/A | AM38: =VLOOKUP(Q38,'Ces, Esc, RTS and Retail'!$J:$J,1,0) -> #N/A | AN38: =VLOOKUP(Q38,'[2]Trip Manager Report(Updated)_V2'!$I:$Z,18,0) -> #N/A | AO38: =VLOOKUP(E38,'Ces, Esc, RTS and Retail'!$L:$L,1,0) -> #N/A | AP38: =VLOOKUP(Q38,Response!$H:$M,5,0) -> #N/A
A39: Wakefit_Retail | B39: ORDER202605prXreM | C39: Paniraj thanthry | D39: #405, 4th floor, Sairam Gardenia, near RGA Tech Park & Decathlon mart, Hadosiddapura, Chikkakannalli, Kodathi JHC, Karnatak | E39: 560035 | F39: 8431567630 | H39: WEWB7860HYSTESSERCW | I39: 78x60 inch | J39: furniture | K39: 1001033590 | L39: Engineered Wood Bed | M39: FG01 | N39: 1 | O39: ONLINE | P39: 26060590009799 | Q39: WFFI459754 | R39: BLR LOCAL | S39: Normal Order | T39: Docketed | U39: 2026-05-20 | V39: 2026-05-28 | W39: 2026-06-21 | X39: 2026-06-22 | Y39: 2026-06-19T22:21:15 | AA39: Breached | AB39: 0 | AD39: =VLOOKUP(Q39,'[1]an1asv_22-06-2026_06-23-43'!$B:$OA,3,0) -> reachedathub | AE39: =VLOOKUP(Q39,'[1]an1asv_22-06-2026_06-23-43'!$B:$OA,147,0) -> Customer Request for Future Date Delivery | AF39: =VLOOKUP(Q39,'[1]an1asv_22-06-2026_06-23-43'!$B:$OA,48,0) -> 46197 | AG39: =VLOOKUP(F39,Response!$A:$B,2,0) -> #N/A | AH39: CFR | AI39: =AF39 -> 46197 | AJ39: =VLOOKUP(B39,'Ces, Esc, RTS and Retail'!$A:$B,2,0) -> #N/A | AK39: =VLOOKUP(F39,'Ces, Esc, RTS and Retail'!$D:$F,3,0) -> #N/A | AL39: =VLOOKUP(B39,'Ces, Esc, RTS and Retail'!$H:$H,1,0) -> #N/A | AM39: =VLOOKUP(Q39,'Ces, Esc, RTS and Retail'!$J:$J,1,0) -> #N/A | AN39: =VLOOKUP(Q39,'[2]Trip Manager Report(Updated)_V2'!$I:$Z,18,0) -> #N/A | AO39: =VLOOKUP(E39,'Ces, Esc, RTS and Retail'!$L:$L,1,0) -> #N/A | AP39: =VLOOKUP(Q39,Response!$H:$M,5,0) -> #N/A
A40: Wakefit_Retail | B40: ORDER202605Z3H3cF | C40: Umar Lone | D40: Ajmera Lakeside Paradise, Flat No. D-205, D Block, 2nd Floor, Kempanahalli, Attur Layout, Yelahanka | E40: 560064 | F40: 9108520725 | G40: 950117183 | H40: WDINEARVWAC1NTBK | J40: furniture | K40: 1001026062 | L40: Metal Dining Chair | M40: FG01 | N40: 1 | O40: ONLINE | P40: 26060590010231 | Q40: WFFWI223215 | R40: BLR LOCAL | S40: Normal Order | T40: Docketed | U40: 2026-05-28 | V40: 2026-05-28 | W40: 2026-06-21 | X40: 2026-06-22 | Y40: 2026-06-21T11:41:40 | AA40: Breached | AB40: 0 | AD40: =VLOOKUP(Q40,'[1]an1asv_22-06-2026_06-23-43'!$B:$OA,3,0) -> reachedathub | AE40: =VLOOKUP(Q40,'[1]an1asv_22-06-2026_06-23-43'!$B:$OA,147,0) -> 0 | AF40: =VLOOKUP(Q40,'[1]an1asv_22-06-2026_06-23-43'!$B:$OA,48,0) -> 46195 | AG40: =VLOOKUP(F40,Response!$A:$B,2,0) -> 1 | AH40: Planned | AJ40: =VLOOKUP(B40,'Ces, Esc, RTS and Retail'!$A:$B,2,0) -> #N/A | AK40: =VLOOKUP(F40,'Ces, Esc, RTS and Retail'!$D:$F,3,0) -> #N/A | AL40: =VLOOKUP(B40,'Ces, Esc, RTS and Retail'!$H:$H,1,0) -> #N/A | AM40: =VLOOKUP(Q40,'Ces, Esc, RTS and Retail'!$J:$J,1,0) -> #N/A | AN40: =VLOOKUP(Q40,'[2]Trip Manager Report(Updated)_V2'!$I:$Z,18,0) -> #N/A | AO40: =VLOOKUP(E40,'Ces, Esc, RTS and Retail'!$L:$L,1,0) -> #N/A | AP40: =VLOOKUP(Q40,Response!$H:$M,5,0) -> #N/A
...

Sheet Route plan  23.06.2026
A1: Platform | B1: order_random_id | C1: cx_name | D1: address | E1: pincode | F1: Route | G1: item_sku | H1: mobile_number | I1: alternate_mobile_number | J1: item_sku | K1: item_dimensions | L1: scm_master_category | M1: Material_code | N1: Product_Type | O1: storage_location | P1: item_quantity | Q1: payment_type | R1: invoice_number | S1: docket_number | T1: LP | U1: Order_Type | V1: Order_Status | W1: Order_Date | X1: Order_Confirmed_Date | Y1: promised_dispatch | Z1: Promised_EDD | AA1: docket_timestamp | AB1: shipped_timestamp | AC1: priority_local | AD1: escalated | AE1: escalation_type | AF1: Status | AG1: Previous Reason | AH1: Previous date | AI1: Response | AJ1: Planning | AK1: Date | AL1: Retail | AM1: CES | AN1: ESC | AO1: RTS | AP1: NDR | AQ1: ODA | AR1: Manual | AS1: qsqs
A2: Wakefit | B2: ORDER202606MZ0ql4 | C2: Asha P | D2: 26/1, 2, Harshith, 10th Main Road, Shivanagar, Rajajinagar | E2: 560010 | F2: 1 | G2: WEWB7230SALT | H2: 9844267875 | I2: 9844267875 | J2: WEWB7230SALT | K2: 72x30 inch | L2: furniture | M2: 1001019160 | N2: Engineered Wood Bed | O2: FG01 | P2: 1 | Q2: ONLINE | R2: 26060590010927 | S2: WFFI461091 | T2: BLR LOCAL | U2: Normal Order | V2: Docketed | W2: 2026-06-19 | X2: 2026-06-19 | Y2: 2026-06-22 | Z2: 2026-06-23 | AA2: 2026-06-22T11:07:33 | AC2: Breached | AD2: 0 | AF2: reachedathub | AG2: 0 | AH2: 46195 | AI2: 1 | AJ2: Planned | AL2: #N/A | AM2: #N/A | AN2: #N/A | AO2: #N/A | AP2: #N/A | AQ2: #N/A | AR2: #N/A | AS2: #N/A
A3: Wakefit | B3: ORDER202606wrov0N | C3: Manish Chopra | D3: 51, 2, Jaya Govindam, 51, 4th Cross Rd, Raghavendra Colony, Chamrajpet, | E3: 560018 | F3: 1 | G3: WEWB7860STAURUSR2 | H3: 8088486035 | I3: 8088486035 | J3: WEWB7860STAURUSR2 | K3: 78x60 inch | L3: furniture | M3: 1003000472 | N3: Engineered Wood Bed | O3: FG01 | P3: 1 | Q3: ONLINE | R3: 26060590010374 | S3: WFFI460706 | T3: BLR LOCAL | U3: Normal Order | V3: Docketed | W3: 2026-06-18 | X3: 2026-06-18 | Y3: 2026-06-21 | Z3: 2026-06-22 | AA3: 2026-06-21T13:37:20 | AC3: Breached | AD3: 0 | AF3: reachedathub | AG3: 0 | AH3: 46195 | AI3: 1 | AJ3: Planned | AL3: #N/A | AM3: #N/A | AN3: #N/A | AO3: #N/A | AP3: #N/A | AQ3: #N/A | AR3: #N/A | AS3: #N/A
A4: Amazon | B4: 405-5771125-9023561 | C4: Sinchana | D4: 3rd floor, #126/A, KN extension 3rd cross triveni road, Yeshwanthpur | E4: 560022 | F4: 1 | G4: WSTEDWIN | H4: 6361107591 | I4: 6361107591 | J4: WSTEDWIN | L4: furniture | M4: 1001013646 | N4: Study Table | O4: FG01 | P4: 1 | Q4: ONLINE | R4: 26060590009254 | S4: WFFI459005 | T4: BLR LOCAL | U4: Normal Order | V4: Shipped | W4: 2026-06-14 | X4: 2026-06-14 | Y4: 2026-06-17 | Z4: 2026-06-20 | AA4: 2026-06-18T17:38:08 | AB4: 2026-06-19T21:04:03 | AC4: Breached | AD4: 0 | AF4: reachedathub | AG4: INSUFFICIENT TIME | AH4: 46195 | AI4: 1 | AJ4: Planned | AL4: #N/A | AM4: #N/A | AN4: #N/A | AO4: #N/A | AP4: #N/A | AQ4: #N/A | AR4: #N/A | AS4: #N/A
A5: Wakefit | B5: ORDER202606mdgh33 | C5: Sachin Dengre | D5: 807, 8, Vaishnavi Ars Gardenia, Ayyappa Temple Road, T Dasarhalli | E5: 560057 | F5: 1 | G5: WEWB7872STAURUSMA | H5: 9902665787 | I5: 9902665787 | J5: WEWB7872STAURUSMA | K5: 78x72 inch | L5: furniture | M5: 1001024787 | N5: Engineered Wood Bed | O5: FG01 | P5: 1 | Q5: ONLINE | R5: 26060590010871 | S5: WFFI461040 | T5: BLR LOCAL | U5: Normal Order | V5: Docketed | W5: 2026-06-20 | X5: 2026-06-20 | Y5: 2026-06-22 | Z5: 2026-06-23 | AA5: 2026-06-22T10:52:36 | AC5: Breached | AD5: 0 | AF5: reachedathub | AG5: 0 | AH5: 46195 | AI5: 1 | AJ5: Planned | AL5: #N/A | AM5: #N/A | AN5: #N/A | AO5: #N/A | AP5: #N/A | AQ5: #N/A | AR5: #N/A | AS5: #N/A
A6: Wakefit | B6: ORDER202606PT4e4u | C6: Raja Singh | D6: No. 71, 4, 5th Cross Ramaiah Layout, 1st Main Road Hegganahalli | E6: 560058 | F6: 1 | G6: WEWB7860SUPOPLTAURUSR2 | H6: 8095668682 | I6: 8095668682 | J6: WEWB7860SUPOPLTAURUSR2 | K6: 78x60 inch | L6: furniture | M6: 1007003118 | N6: Engineered Wood Bed | O6: FG01 | P6: 1 | Q6: ONLINE | R6: 26060590010862 | S6: WFFI461034 | T6: BLR LOCAL | U6: Normal Order | V6: Docketed | W6: 2026-06-02 | X6: 2026-06-02 | Y6: 2026-06-22 | Z6: 2026-06-23 | AA6: 2026-06-22T10:52:26 | AC6: Breached | AD6: 0 | AF6: reachedathub | AG6: 0 | AH6: 46195 | AI6: 1 | AJ6: Planned | AL6: #N/A | AM6: #N/A | AN6: #N/A | AO6: #N/A | AP6: #N/A | AQ6: #N/A | AR6: #N/A | AS6: #N/A
A7: Wakefit | B7: ORDER202606VkHrB7 | C7: Vinod | D7: Floor-20, Flat No 25291 , 29 th floor, building 2 tower 5 | E7: 560073 | F7: 1 | G7: WEWB7236NONTAURUSR2 | H7: 9972781519 | J7: WEWB7236NONTAURUSR2 | K7: 72x36 inch | L7: furniture | M7: 1007100455 | N7: Engineered Wood Bed | O7: FG01 | P7: 1 | Q7: ONLINE | R7: 26060590010673 | S7: WFFI460906 | T7: BLR LOCAL | U7: Normal Order | V7: Docketed | W7: 2026-06-07 | X7: 2026-06-07 | Y7: 2026-06-27 | Z7: 2026-06-28 | AA7: 2026-06-22T09:36:56 | AC7: P1 | AD7: 0 | AF7: reachedathub | AG7: 0 | AH7: 46195 | AI7: 1 | AJ7: Planned | AL7: #N/A | AM7: #N/A | AN7: #N/A | AO7: #N/A | AP7: #N/A | AQ7: #N/A | AR7: #N/A | AS7: #N/A
A8: Wakefit | B8: ORDER202606VkHrB7 | C8: Vinod | D8: Floor-20, Flat No 25291 , 29 th floor, building 2 tower 5 | E8: 560073 | F8: 1 | G8: WEWB7560STAURUSR2 | H8: 9972781519 | J8: WEWB7560STAURUSR2 | K8: 75x60 inch | L8: furniture | M8: 1001024999 | N8: Engineered Wood Bed | O8: FG01 | P8: 1 | Q8: ONLINE | R8: 26060590010681 | S8: WFFI460912 | T8: BLR LOCAL | U8: Normal Order | V8: Docketed | W8: 2026-06-07 | X8: 2026-06-07 | Y8: 2026-06-23 | Z8: 2026-06-24 | AA8: 2026-06-22T09:37:01 | AC8: P0 | AD8: 0 | AF8: reachedathub | AG8: 0 | AH8: 46195 | AI8: 1 | AJ8: Planned | AL8: #N/A | AM8: #N/A | AN8: #N/A | AO8: #N/A | AP8: #N/A | AQ8: #N/A | AR8: #N/A | AS8: #N/A
A9: Wakefit | B9: ORDER202606vZLfew | C9: Vinod | D9: 25291, 29, Prestige Jindal city, 25291..Prestige Jindal city | E9: 560073 | F9: 1 | G9: WCFTLEONISCW | H9: 9972781519 | I9: 9972781519 | J9: WCFTLEONISCW | L9: furniture | M9: 1007003568 | N9: Coffee Table | O9: FG01 | P9: 1 | Q9: ONLINE | R9: 26060590010846 | S9: WFFI461018 | T9: BLR LOCAL | U9: Normal Order | V9: Docketed | W9: 2026-06-20 | X9: 2026-06-20 | Y9: 2026-06-23 | Z9: 2026-06-24 | AA9: 2026-06-22T10:52:07 | AC9: P0 | AD9: 0 | AF9: reachedathub | AG9: 0 | AH9: 46195 | AI9: 1 | AJ9: Planned | AL9: #N/A | AM9: #N/A | AN9: #N/A | AO9: #N/A | AP9: #N/A | AQ9: #N/A | AR9: #N/A | AS9: #N/A
A10: Wakefit | B10: ORDER202606fHqbC7 | C10: Markandeya BS | D10: NO 87, 1, NANDAGOKULA, ANCHEPALYA ROAD TOTADA GUDDADAHALLY | E10: 560073 | F10: 1 | G10: WEWB7230SCRX | H10: 9632329741 | I10: 9632329741 | J10: WEWB7230SCRX | K10: 72x30 inch | L10: furniture | M10: 1001019159 | N10: Engineered Wood Bed | O10: FG01 | P10: 1 | Q10: COD | R10: 26060590010829 | S10: WFFI461000 | T10: BLR LOCAL | U10: Normal Order | V10: Docketed | W10: 2026-06-20 | X10: 2026-06-20 | Y10: 2026-06-23 | Z10: 2026-06-24 | AA10: 2026-06-22T10:51:44 | AC10: P0 | AD10: 0 | AF10: reachedathub | AG10: 0 | AH10: 46195 | AI10: 1 | AJ10: Planned | AL10: #N/A | AM10: #N/A | AN10: #N/A | AO10: #N/A | AP10: #N/A | AQ10: #N/A | AR10: #N/A | AS10: #N/A
